Workbook

Sheet Легенда
A1: 3D-Print — номенклатура, собівартість, продажі, наявність
A2: v5 · 2026-07-31 · SKU перейменовано FIG-CHARM-001 → BR-CHARM-001 (брелоки отримують префікс BR-, префікс FIG- лишається за самостійними фігурками); Номенклатура A3 оновлена реальними даними після фото від Сергія (партія 36 шт = заготовки під Track 2, готового товару 0 шт).
A4: Що нового у v2
A5: Власник зафіксував фінансову модель 2026-07-28: собівартість Сергія повертається йому першою, залишковий маржинальний прибуток ділиться 50/50. Порівняння з варіантом «% від виручки» більше не потрібне — той варіант знято. Вкладки «Продажі» та «Аналітика» переписані під цю формулу. v3→v4 (2026-07-31, той самий день): додано нову вкладку «Виплати» — трекінг періодів нарахувань і фактичних виплат Сергію (див. розділ нижче). Два пункти з «Відомих відкритих питань» закриті остаточно: графік/модель виплат (вкладка «Виплати» знімає питання) і ліміт знижки без узгодження (підтверджено — окремого числового ліміту немає, усе централізовано з Сергієм). v4→v5 (2026-07-31, той самий день): власник підтвердив фото готової партії (36 заготовок-брелоків Чармандер, ще без ланцюжка/карабіна — фурнітура окремо). Уточнено: ця партія 36 шт замовлена одразу як викуп під Track 2 «Маркетингова плюшка», а не під продаж на сайті — отже фактичний залишок готового товару під Track 1 (продаж) = 0 шт, поки не буде окремого друку під продаж. Власник підняв процесне питання: як фіксувати собівартість Track-2 закупівлі, коли до неї додається фурнітура (ланцюжок/карабін) поверх ціни від Сергія — відкрите питання, див. Номенклатура M3 і 3D-P-002/3D-P-004.
A7: Формула розрахунку (усі вкладки)
A8: • Маржинальний прибуток = Фактична ціна продажу (після знижки) − Собівартість Сергія − Витрати BoosterShop.
A9: • Нараховано Сергію = Собівартість Сергія + 50% × Маржинальний прибуток.
A10: • Маржа BoosterShop = 50% × Маржинальний прибуток.
A11: • Якщо Маржинальний прибуток від'ємний — формула НЕ застосовується автоматично: рядок отримує статус «ЗБИТКОВИЙ — рішення власника», сума не рахується, поки власник не вирішить, хто покриває збиток.
A13: Два треки — не плутати з формулою вище
A14: Трек 1 — «Продаж на сайті» (вкладка Продажі) | B14: Формула вище застосовується тут повністю.
A15: Трек 2 — «Маркетингова плюшка» (вкладка Маркетингові_плюшки) | B15: Формула вище НЕ застосовується — це пряма закупівля готового виробу в Сергія за мінімальною націнкою, без продажної виручки і без 50/50. 31.07: додано колонки I–K (Фурнітура за од. / Собівартість за од. Сергій+фурнітура / Собівартість партії) — власник хотів фіксувати повну собівартість Track-2 закупівлі, коли до ціни від Сергія (D) додається своя фурнітура (ланцюжок/карабін), не лише ціну Сергія. Колонка D і далі означає лише те, що сплачено Сергію (для узгодження з «Виплати»); I — фурнітура окремо; J/K — розрахункова повна собівартість, формули, не редагувати вручну.
A17: Важливе спрощення (поки що)
A18: «Собівартість Сергію» тепер = вартість матеріалу (Номенклатура, колонка K, формула I×J/1000) + фурнітура за одиницю (колонка N, напр. ланцюжок/карабін). Повне визначення з обговорення включає ще електрику, амортизацію принтера, працю, витратники й ліцензію — цей файл їх ще НЕ рахує окремо. Додайте вручну в «Витрати BoosterShop» або в примітку, доки калькулятор не розшириться.
A20: Хто що заповнює
A21: Друг | B21: Номенклатура: колонки G–L (час друку, матеріал, витрата, ціна матеріалу/кг, дата, примітки) та N (фурнітура).
A22: Власник | B22: Номенклатура: колонки A–F (SKU, назва, франшиза, тип, трек, статус). Продажі: фактична ціна, витрати BoosterShop, канал, замовлення. Маркетингові_плюшки. Аналітика: цінові сценарії. Виплати: Період, Дата фактичної виплати, Статус, Примітки.
A23: Обидва (за домовленістю) | B23: Можна заповнювати Друк-лог і Продажі спільно — головне не редагувати одну клітинку одночасно.
A24: Ніхто вручну | B24: Наявність — рахується автоматично формулами з інших вкладок. Не вводити туди числа руками. Виплати: колонки «Нараховано Сергію за період» і «Термін перевірки Сергієм» — теж формули, не вводити руками.
A26: Колірний код
A27: Синій текст | B27: Клітинка для ручного вводу
A28: Чорний текст | B28: Формула — не змінювати вручну
A29: Жовта заливка | B29: Ключове припущення / потрібне рішення власника (напр. % прибутку за конкретним SKU)
A30: Сірий курсив | B30: Приклад / референс-рядок — замінити реальними даними
A32: Відомі відкриті питання (станом на 2026-07-31)
A33: • Закупівельна ціна за трек «Маркетингова плюшка» (ВИРІШЕНО, 31.07): фіксованої формули/відсотка немає. Сергій вводить ціну вручну для кожного SKU в колонці «Ціна закупівлі за од.» (вкладка Маркетингові_плюшки), орієнтуючись на складність виробу (просте/швидке — ближче до собівартості; складне — дорожче). Без автоматизації.
A34: • Поріг суми замовлення, з якого йде безкоштовна плюшка — не визначено (вкладка Маркетингові_плюшки, жовта клітинка).
A35: • Витрати BoosterShop — пакування ВИРІШЕНО (власник, 31.07): за замовчуванням НЕ додається окремою статтею, покривається маржею; повернутися лише якщо для великих товарів виявиться недооцінка. Комісія оплати тощо — усе ще не заповнено.
A36: • Цінові сценарії на вкладці Аналітика — orientovні; знайдено 30 перевірених ринкових прикладів (задача 3D-P-003), але звірки з реальною собівартістю Сергія по 3-5 SKU ще нема (є лише 1 SKU — Чармандер, і той з відкритими H/J).
A37: • Категорія каталогу для фігурок ще не створена в OpenCart — рішення власника, див. план 3D-P-002.
A38: • Локальний сервер UI поверх цієї таблиці — чи потрібен Другу віддалений доступ, чи лише власнику (план 3D-P, §12).
A39: • Хто покриває збиток при свідомому продажу нижче собівартості (ВИРІШЕНО, 31.07) | B39: Власник. Такий SKU НЕ продається на сайті зі знижкою нижче собівартості Сергія — натомість оформлюється як викуп через вкладку «Маркетингові_плюшки» (Трек 2), який фінансує власник.
A40: • Гарантована мінімальна маржа/оплата за годину Сергію (ВИРІШЕНО, 31.07) | B40: Не потрібна.
A41: • Термін перевірки розрахунку Сергієм перед виплатою (ВИРІШЕНО, 31.07) | B41: 2 дні формально; по факту власник контактує з Сергієм і платить в останній день місяця.
A42: • Графік і модель виплат (ВИРІШЕНО, 31.07): раз на місяць, в кінці місяця, без авансу. 2 дні — формальний термін перевірки розрахунку Сергієм, по факту власник контактує й платить в останній день місяця / наступного дня. Окрема вкладка «Виплати» додана в v4 (трекінг періодів, нарахувань і фактичних виплат) — див. розділ нижче. | B42: Вирішено остаточно, 31.07 — вкладка «Виплати» додана в v4.
A43: • Максимальна знижка без окремого узгодження (ВИРІШЕНО, 31.07): окремого числового ліміту немає. Усі знижки погоджуються з Сергієм централізовано (не автономно на сайті). Введено новий блок у вкладці Продажі — колонки P «Тип знижки», Q «Параметр знижки», R «Погоджено з Сергієм» — див. розділ «Типи знижок» нижче. | B43: Вирішено остаточно, 31.07 — підтверджено власником, окремого числового ліміту немає.
A61: Типи знижок (вкладка Продажі, колонки P/Q/R) — введено 31.07
A62: «% від РРЦ» | B62: Класична знижка у відсотках від РРЦ. Параметр (Q) — сам відсоток, напр. «15%». Колонка E «Фактична ціна за од.» = РРЦ × (1 − %), вводиться вручну.
A63: «N+1 безкоштовно» | B63: Напр. «купи 2, третій безкоштовно» (акційний пакет в межах продажу на сайті, Трек 1). Параметр (Q) — формат типу «3+1». ВІДРІЗНЯЄТЬСЯ від «Маркетингові_плюшки» (Трек 2): там власник окремо викуповує готовий виріб у Сергія під замовлення понад ту ж покупку, без 50/50. Тут — знижка всередині самого продажу, формула 50/50 застосовується як завжди до фактичної ціни.
A64: «Інше» | B64: Будь-який інший формат знижки, не описаний вище — деталі в Q і в Примітках (колонка O).
...

Sheet Номенклатура
A1: SKU | B1: Назва виробу | C1: Франшиза | D1: Тип | E1: Трек | F1: Статус | G1: Час друку, год | H1: Матеріал (пластик) | I1: Витрата матеріалу, г | J1: Ціна матеріалу, грн/кг | K1: Собівартість Сергія (матеріал+фурнітура), грн | L1: Дата оновлення | M1: Примітки | N1: Фурнітура (ланцюжок/карабін), грн/шт
A2: ПРИКЛАД-001 | B2: Приклад розрахунку (ілюстративні цифри) | C2: — | D2: Фігурка | E2: Продаж на сайті | F2: ПРИКЛАД — видалити | G2: 4 | H2: PLA | I2: 120 | J2: 700 | K2: =I2*J2/1000+N2 | L2: 2026-07-28 | M2: Ілюстративні цифри лише для перевірки формул. Замініть/видаліть перед використанням.
A3: BR-CHARM-001 | B3: Брелок Чармандер | C3: Pokemon | D3: Брелок | E3: Продаж на сайті | F3: Реальне фото партії підтверджено власником 31.07 (36 заготовок на друкованому столі). Тип пластику назви немає — власник переказує зі слів Сергія лише що це 'гарний' пластик, дешевший в Україні й дорожчий за кордоном; це не підтверджена специфікація (PLA/PETG/ABS), лишається уточнити у J. Фактично готового товару під продаж 0 шт: усі 36 заготовок замовлені одразу як викуп під Track 2 (маркетингова плюшка), фурнітура (ланцюжок/карабін) ще не приєднана. Track A (продаж на сайті) для цього SKU наразі без реального стоку — потребує рішення власника, чи буде окремий друк під продаж. | G3: 0.1032 | H3: уточнити у Сергія | I3: 2.45 | K3: =I3*J3/1000+N3 | L3: 2026-07-31 | M3: Джерело: скріншоти слайсера + повідомлення власника, 2026-07-31. Партія 36 шт на платформі: 3год43хв друку, філамент 27,79м/88,24г, слайсер-оцінка вартості 136,77 грн (≈3,80 грн/шт). Разовий друк 1 шт: 16 хв, слайсер-оцінка 6,08 грн/шт. Використано дані партії (36 шт) як реалістичний виробничий режим. УВАГА: слайсер-оцінка вартості могла включати не лише чистий пластик (можливо електрику/час) — перед внесенням у колонку J (Ціна матеріалу, грн/кг) уточнити у Сергія, чи це ціна пластику окремо. Тип пластику (PLA/ABS/PETG) також не вказано — уточнити. | 31.07 оновлення: SKU перейменовано з FIG-CHARM-001 на BR-CHARM-001 (це брелок, не окрема фігурка). Реальне фото партії є (не референс/сток). Відкрите процесне питання від власника: як логувати Track-2 закупівлі, коли собівартість = сума Сергію + фурнітура (ланцюжок/карабін) — куди саме заносити (Маркетингові_плюшки vs окрема стаття витрат). Не вирішено, не заповнювати без рішення власника. | N3: 3
A4: (призначити SKU) | B4: Фігурка Генгар | C4: Pokémon | D4: Фігурка | F4: Референс із фото власника — ще не надруковано Другом | K4: =I4*J4/1000+N4 | M4: Товар з референс-фото у чаті 2026-07-28, конкретні товари узгоджуються з Другом окремо
A5: (призначити SKU) | B5: Кейс-покебол «Мяу» (Mew) з хвостом | C5: Pokémon | D5: Функціональний аксесуар | F5: Референс із фото власника — ще не надруковано Другом | K5: =I5*J5/1000+N5 | M5: Товар з референс-фото у чаті 2026-07-28, конкретні товари узгоджуються з Другом окремо
A6: (призначити SKU) | B6: Підставка-олівниця «Дітто» (Ditto) | C6: Pokémon | D6: Функціональний аксесуар | F6: Референс із фото власника — ще не надруковано Другом | K6: =I6*J6/1000+N6 | M6: Товар з референс-фото у чаті 2026-07-28, конкретні товари узгоджуються з Другом окремо
A7: (призначити SKU) | B7: Дек-бокс «Покебол» (набір кольорів) | C7: Pokémon | D7: Функціональний аксесуар | F7: Референс із фото власника — ще не надруковано Другом | K7: =I7*J7/1000+N7 | M7: Товар з референс-фото у чаті 2026-07-28, конкретні товари узгоджуються з Другом окремо
A8: (призначити SKU) | B8: Брелок/фігурка «Онікс» (Onix) | C8: Pokémon | D8: Фігурка | F8: Референс із фото власника — ще не надруковано Другом | K8: =I8*J8/1000+N8 | M8: Товар з референс-фото у чаті 2026-07-28, конкретні товари узгоджуються з Другом окремо
A9: (призначити SKU) | B9: Фігурка Пікачу «крізь стіну» (декор) | C9: Pokémon | D9: Фігурка | F9: Референс із фото власника — ще не надруковано Другом | K9: =I9*J9/1000+N9 | M9: Товар з референс-фото у чаті 2026-07-28, конкретні товари узгоджуються з Другом окремо
K10: =I10*J10/1000+N10
K11: =I11*J11/1000+N11
K12: =I12*J12/1000+N12
K13: =I13*J13/1000+N13
K14: =I14*J14/1000+N14
K15: =I15*J15/1000+N15

Sheet Друк-лог
A1: Дата | B1: SKU | C1: Надруковано, шт | D1: Час друку факт, год | E1: Брак/відходи, шт | F1: Витрачено матеріалу, г (факт) | G1: Собівартість партії, грн | H1: Хто друкував | I1: Примітки
A2: 2026-07-20 | B2: ПРИКЛАД-001 | C2: 5 | D2: 22 | E2: 1 | F2: 600 | G2: =IF(B2="","",C2*IFERROR(INDEX(Номенклатура!$K:$K,MATCH(B2,Номенклатура!$A:$A,0)),0)) | H2: Друг | I2: приклад — видалити
G3: =IF(B3="","",C3*IFERROR(INDEX(Номенклатура!$K:$K,MATCH(B3,Номенклатура!$A:$A,0)),0))
G4: =IF(B4="","",C4*IFERROR(INDEX(Номенклатура!$K:$K,MATCH(B4,Номенклатура!$A:$A,0)),0))
G5: =IF(B5="","",C5*IFERROR(INDEX(Номенклатура!$K:$K,MATCH(B5,Номенклатура!$A:$A,0)),0))
G6: =IF(B6="","",C6*IFERROR(INDEX(Номенклатура!$K:$K,MATCH(B6,Номенклатура!$A:$A,0)),0))
G7: =IF(B7="","",C7*IFERROR(INDEX(Номенклатура!$K:$K,MATCH(B7,Номенклатура!$A:$A,0)),0))
G8: =IF(B8="","",C8*IFERROR(INDEX(Номенклатура!$K:$K,MATCH(B8,Номенклатура!$A:$A,0)),0))
G9: =IF(B9="","",C9*IFERROR(INDEX(Номенклатура!$K:$K,MATCH(B9,Номенклатура!$A:$A,0)),0))
G10: =IF(B10="","",C10*IFERROR(INDEX(Номенклатура!$K:$K,MATCH(B10,Номенклатура!$A:$A,0)),0))
G11: =IF(B11="","",C11*IFERROR(INDEX(Номенклатура!$K:$K,MATCH(B11,Номенклатура!$A:$A,0)),0))
G12: =IF(B12="","",C12*IFERROR(INDEX(Номенклатура!$K:$K,MATCH(B12,Номенклатура!$A:$A,0)),0))
G13: =IF(B13="","",C13*IFERROR(INDEX(Номенклатура!$K:$K,MATCH(B13,Номенклатура!$A:$A,0)),0))
G14: =IF(B14="","",C14*IFERROR(INDEX(Номенклатура!$K:$K,MATCH(B14,Номенклатура!$A:$A,0)),0))
... G39: =IF(B39="","",C39*IFERROR(INDEX(Номенклатура!$K:$K,MATCH(B39,Номенклатура!$A:$A,0)),0))

Sheet Продажі
A1: Дата | B1: SKU | C1: Назва | D1: Кількість | E1: Фактична ціна за од., грн (після знижки) | F1: Собівартість Сергія за од., грн | G1: Витрати BoosterShop за од., грн | H1: % прибутку Сергію | I1: Маржинальний прибуток за од., грн | J1: Статус | K1: Нараховано Сергію, грн | L1: Дохід Booster Shop, грн | M1: Канал | N1: № замовлення | O1: Примітки | P1: Тип знижки | Q1: Параметр знижки | R1: Погоджено з Сергієм (Так/Ні) | S1: Період (авто, РРРР-ММ)
A2: 2026-07-25 | B2: ПРИКЛАД-001 | C2: =IF(B2="","",IFERROR(INDEX(Номенклатура!$B:$B,MATCH(B2,Номенклатура!$A:$A,0)),"")) | D2: 1 | E2: 350 | F2: =IF(B2="","",IFERROR(INDEX(Номенклатура!$K:$K,MATCH(B2,Номенклатура!$A:$A,0)),0)) | G2: 20 | H2: 0.5 | I2: =IF(OR(B2="",E2=""),"",E2-F2-G2) | J2: =IF(I2="","",IF(I2<0,"⚠ ЗБИТКОВИЙ — рішення власника","ОК")) | K2: =IF(OR(I2="",I2<0),"див. Статус",D2*(F2+H2*I2)) | L2: =IF(OR(I2="",I2<0),"див. Статус",D2*I2*(1-H2)) | M2: Сайт | N2: — | O2: приклад — видалити; ціна й витрати тут довільні, не рішення власника | S2: =IF(A2="","",LEFT(A2,7))
C3: =IF(B3="","",IFERROR(INDEX(Номенклатура!$B:$B,MATCH(B3,Номенклатура!$A:$A,0)),"")) | F3: =IF(B3="","",IFERROR(INDEX(Номенклатура!$K:$K,MATCH(B3,Номенклатура!$A:$A,0)),0)) | I3: =IF(OR(B3="",E3=""),"",E3-F3-G3) | J3: =IF(I3="","",IF(I3<0,"⚠ ЗБИТКОВИЙ — рішення власника","ОК")) | K3: =IF(OR(I3="",I3<0),"див. Статус",D3*(F3+H3*I3)) | L3: =IF(OR(I3="",I3<0),"див. Статус",D3*I3*(1-H3)) | S3: =IF(A3="","",LEFT(A3,7))
C4: =IF(B4="","",IFERROR(INDEX(Номенклатура!$B:$B,MATCH(B4,Номенклатура!$A:$A,0)),"")) | F4: =IF(B4="","",IFERROR(INDEX(Номенклатура!$K:$K,MATCH(B4,Номенклатура!$A:$A,0)),0)) | I4: =IF(OR(B4="",E4=""),"",E4-F4-G4) | J4: =IF(I4="","",IF(I4<0,"⚠ ЗБИТКОВИЙ — рішення власника","ОК")) | K4: =IF(OR(I4="",I4<0),"див. Статус",D4*(F4+H4*I4)) | L4: =IF(OR(I4="",I4<0),"див. Статус",D4*I4*(1-H4)) | S4: =IF(A4="","",LEFT(A4,7))
C5: =IF(B5="","",IFERROR(INDEX(Номенклатура!$B:$B,MATCH(B5,Номенклатура!$A:$A,0)),"")) | F5: =IF(B5="","",IFERROR(INDEX(Номенклатура!$K:$K,MATCH(B5,Номенклатура!$A:$A,0)),0)) | I5: =IF(OR(B5="",E5=""),"",E5-F5-G5) | J5: =IF(I5="","",IF(I5<0,"⚠ ЗБИТКОВИЙ — рішення власника","ОК")) | K5: =IF(OR(I5="",I5<0),"див. Статус",D5*(F5+H5*I5)) | L5: =IF(OR(I5="",I5<0),"див. Статус",D5*I5*(1-H5)) | S5: =IF(A5="","",LEFT(A5,7))
C6: =IF(B6="","",IFERROR(INDEX(Номенклатура!$B:$B,MATCH(B6,Номенклатура!$A:$A,0)),"")) | F6: =IF(B6="","",IFERROR(INDEX(Номенклатура!$K:$K,MATCH(B6,Номенклатура!$A:$A,0)),0)) | I6: =IF(OR(B6="",E6=""),"",E6-F6-G6) | J6: =IF(I6="","",IF(I6<0,"⚠ ЗБИТКОВИЙ — рішення власника","ОК")) | K6: =IF(OR(I6="",I6<0),"див. Статус",D6*(F6+H6*I6)) | L6: =IF(OR(I6="",I6<0),"див. Статус",D6*I6*(1-H6)) | S6: =IF(A6="","",LEFT(A6,7))
C7: =IF(B7="","",IFERROR(INDEX(Номенклатура!$B:$B,MATCH(B7,Номенклатура!$A:$A,0)),"")) | F7: =IF(B7="","",IFERROR(INDEX(Номенклатура!$K:$K,MATCH(B7,Номенклатура!$A:$A,0)),0)) | I7: =IF(OR(B7="",E7=""),"",E7-F7-G7) | J7: =IF(I7="","",IF(I7<0,"⚠ ЗБИТКОВИЙ — рішення власника","ОК")) | K7: =IF(OR(I7="",I7<0),"див. Статус",D7*(F7+H7*I7)) | L7: =IF(OR(I7="",I7<0),"див. Статус",D7*I7*(1-H7)) | S7: =IF(A7="","",LEFT(A7,7))
C8: =IF(B8="","",IFERROR(INDEX(Номенклатура!$B:$B,MATCH(B8,Номенклатура!$A:$A,0)),"")) | F8: =IF(B8="","",IFERROR(INDEX(Номенклатура!$K:$K,MATCH(B8,Номенклатура!$A:$A,0)),0)) | I8: =IF(OR(B8="",E8=""),"",E8-F8-G8) | J8: =IF(I8="","",IF(I8<0,"⚠ ЗБИТКОВИЙ — рішення власника","ОК")) | K8: =IF(OR(I8="",I8<0),"див. Статус",D8*(F8+H8*I8)) | L8: =IF(OR(I8="",I8<0),"див. Статус",D8*I8*(1-H8)) | S8: =IF(A8="","",LEFT(A8,7))
C9: =IF(B9="","",IFERROR(INDEX(Номенклатура!$B:$B,MATCH(B9,Номенклатура!$A:$A,0)),"")) | F9: =IF(B9="","",IFERROR(INDEX(Номенклатура!$K:$K,MATCH(B9,Номенклатура!$A:$A,0)),0)) | I9: =IF(OR(B9="",E9=""),"",E9-F9-G9) | J9: =IF(I9="","",IF(I9<0,"⚠ ЗБИТКОВИЙ — рішення власника","ОК")) | K9: =IF(OR(I9="",I9<0),"див. Статус",D9*(F9+H9*I9)) | L9: =IF(OR(I9="",I9<0),"див. Статус",D9*I9*(1-H9)) | S9: =IF(A9="","",LEFT(A9,7))
C10: =IF(B10="","",IFERROR(INDEX(Номенклатура!$B:$B,MATCH(B10,Номенклатура!$A:$A,0)),"")) | F10: =IF(B10="","",IFERROR(INDEX(Номенклатура!$K:$K,MATCH(B10,Номенклатура!$A:$A,0)),0)) | I10: =IF(OR(B10="",E10=""),"",E10-F10-G10) | J10: =IF(I10="","",IF(I10<0,"⚠ ЗБИТКОВИЙ — рішення власника","ОК")) | K10: =IF(OR(I10="",I10<0),"див. Статус",D10*(F10+H10*I10)) | L10: =IF(OR(I10="",I10<0),"див. Статус",D10*I10*(1-H10)) | S10: =IF(A10="","",LEFT(A10,7))
C11: =IF(B11="","",IFERROR(INDEX(Номенклатура!$B:$B,MATCH(B11,Номенклатура!$A:$A,0)),"")) | F11: =IF(B11="","",IFERROR(INDEX(Номенклатура!$K:$K,MATCH(B11,Номенклатура!$A:$A,0)),0)) | I11: =IF(OR(B11="",E11=""),"",E11-F11-G11) | J11: =IF(I11="","",IF(I11<0,"⚠ ЗБИТКОВИЙ — рішення власника","ОК")) | K11: =IF(OR(I11="",I11<0),"див. Статус",D11*(F11+H11*I11)) | L11: =IF(OR(I11="",I11<0),"див. Статус",D11*I11*(1-H11)) | S11: =IF(A11="","",LEFT(A11,7))
C12: =IF(B12="","",IFERROR(INDEX(Номенклатура!$B:$B,MATCH(B12,Номенклатура!$A:$A,0)),"")) | F12: =IF(B12="","",IFERROR(INDEX(Номенклатура!$K:$K,MATCH(B12,Номенклатура!$A:$A,0)),0)) | I12: =IF(OR(B12="",E12=""),"",E12-F12-G12) | J12: =IF(I12="","",IF(I12<0,"⚠ ЗБИТКОВИЙ — рішення власника","ОК")) | K12: =IF(OR(I12="",I12<0),"див. Статус",D12*(F12+H12*I12)) | L12: =IF(OR(I12="",I12<0),"див. Статус",D12*I12*(1-H12)) | S12: =IF(A12="","",LEFT(A12,7))
C13: =IF(B13="","",IFERROR(INDEX(Номенклатура!$B:$B,MATCH(B13,Номенклатура!$A:$A,0)),"")) | F13: =IF(B13="","",IFERROR(INDEX(Номенклатура!$K:$K,MATCH(B13,Номенклатура!$A:$A,0)),0)) | I13: =IF(OR(B13="",E13=""),"",E13-F13-G13) | J13: =IF(I13="","",IF(I13<0,"⚠ ЗБИТКОВИЙ — рішення власника","ОК")) | K13: =IF(OR(I13="",I13<0),"див. Статус",D13*(F13+H13*I13)) | L13: =IF(OR(I13="",I13<0),"див. Статус",D13*I13*(1-H13)) | S13: =IF(A13="","",LEFT(A13,7))
C14: =IF(B14="","",IFERROR(INDEX(Номенклатура!$B:$B,MATCH(B14,Номенклатура!$A:$A,0)),"")) | F14: =IF(B14="","",IFERROR(INDEX(Номенклатура!$K:$K,MATCH(B14,Номенклатура!$A:$A,0)),0)) | I14: =IF(OR(B14="",E14=""),"",E14-F14-G14) | J14: =IF(I14="","",IF(I14<0,"⚠ ЗБИТКОВИЙ — рішення власника","ОК")) | K14: =IF(OR(I14="",I14<0),"див. Статус",D14*(F14+H14*I14)) | L14: =IF(OR(I14="",I14<0),"див. Статус",D14*I14*(1-H14)) | S14: =IF(A14="","",LEFT(A14,7))
... C39: =IF(B39="","",IFERROR(INDEX(Номенклатура!$B:$B,MATCH(B39,Номенклатура!$A:$A,0)),"")) | F39: =IF(B39="","",IFERROR(INDEX(Номенклатура!$K:$K,MATCH(B39,Номенклатура!$A:$A,0)),0)) | I39: =IF(OR(B39="",E39=""),"",E39-F39-G39) | J39: =IF(I39="","",IF(I39<0,"⚠ ЗБИТКОВИЙ — рішення власника","ОК")) | K39: =IF(OR(I39="",I39<0),"див. Статус",D39*(F39+H39*I39)) | L39: =IF(OR(I39="",I39<0),"див. Статус",D39*I39*(1-H39)) | S39: =IF(A39="","",LEFT(A39,7))

Sheet Виплати
A1: Період (РРРР-ММ) | B1: Нараховано Сергію за період, грн | C1: Термін перевірки Сергієм | D1: Дата фактичної виплати | E1: Статус | F1: Примітки
A2: 2026-07 | B2: =IF(A2="","",SUMIFS(Продажі!$K:$K,Продажі!$S:$S,A2)) | C2: =IF(A2="","",TEXT(EOMONTH(DATEVALUE(A2&"-01"),0)+2,"YYYY-MM-DD")) | D2: 2026-08-02 | E2: ПРИКЛАД — видалити | F2: приклад — видалити; сума в B тягнеться з реального прикладу-рядка в «Продажі», не рішення власника
B3: =IF(A3="","",SUMIFS(Продажі!$K:$K,Продажі!$S:$S,A3)) | C3: =IF(A3="","",TEXT(EOMONTH(DATEVALUE(A3&"-01"),0)+2,"YYYY-MM-DD"))
B4: =IF(A4="","",SUMIFS(Продажі!$K:$K,Продажі!$S:$S,A4)) | C4: =IF(A4="","",TEXT(EOMONTH(DATEVALUE(A4&"-01"),0)+2,"YYYY-MM-DD"))
B5: =IF(A5="","",SUMIFS(Продажі!$K:$K,Продажі!$S:$S,A5)) | C5: =IF(A5="","",TEXT(EOMONTH(DATEVALUE(A5&"-01"),0)+2,"YYYY-MM-DD"))
B6: =IF(A6="","",SUMIFS(Продажі!$K:$K,Продажі!$S:$S,A6)) | C6: =IF(A6="","",TEXT(EOMONTH(DATEVALUE(A6&"-01"),0)+2,"YYYY-MM-DD"))
B7: =IF(A7="","",SUMIFS(Продажі!$K:$K,Продажі!$S:$S,A7)) | C7: =IF(A7="","",TEXT(EOMONTH(DATEVALUE(A7&"-01"),0)+2,"YYYY-MM-DD"))
B8: =IF(A8="","",SUMIFS(Продажі!$K:$K,Продажі!$S:$S,A8)) | C8: =IF(A8="","",TEXT(EOMONTH(DATEVALUE(A8&"-01"),0)+2,"YYYY-MM-DD"))
B9: =IF(A9="","",SUMIFS(Продажі!$K:$K,Продажі!$S:$S,A9)) | C9: =IF(A9="","",TEXT(EOMONTH(DATEVALUE(A9&"-01"),0)+2,"YYYY-MM-DD"))
B10: =IF(A10="","",SUMIFS(Продажі!$K:$K,Продажі!$S:$S,A10)) | C10: =IF(A10="","",TEXT(EOMONTH(DATEVALUE(A10&"-01"),0)+2,"YYYY-MM-DD"))
B11: =IF(A11="","",SUMIFS(Продажі!$K:$K,Продажі!$S:$S,A11)) | C11: =IF(A11="","",TEXT(EOMONTH(DATEVALUE(A11&"-01"),0)+2,"YYYY-MM-DD"))
B12: =IF(A12="","",SUMIFS(Продажі!$K:$K,Продажі!$S:$S,A12)) | C12: =IF(A12="","",TEXT(EOMONTH(DATEVALUE(A12&"-01"),0)+2,"YYYY-MM-DD"))
B13: =IF(A13="","",SUMIFS(Продажі!$K:$K,Продажі!$S:$S,A13)) | C13: =IF(A13="","",TEXT(EOMONTH(DATEVALUE(A13&"-01"),0)+2,"YYYY-MM-DD"))
B14: =IF(A14="","",SUMIFS(Продажі!$K:$K,Продажі!$S:$S,A14)) | C14: =IF(A14="","",TEXT(EOMONTH(DATEVALUE(A14&"-01"),0)+2,"YYYY-MM-DD"))
... B30: =IF(A30="","",SUMIFS(Продажі!$K:$K,Продажі!$S:$S,A30)) | C30: =IF(A30="","",TEXT(EOMONTH(DATEVALUE(A30&"-01"),0)+2,"YYYY-MM-DD"))

Sheet Маркетингові_плюшки
A1: Дата | B1: SKU | C1: Закуплено в Друга, шт | D1: Ціна закупівлі за од., грн | E1: Сума закупівлі, грн | F1: Видано як бонус, шт | G1: До замовлення № | H1: Примітки | I1: Фурнітура за од. (ланцюжок/карабін), грн | J1: Собівартість за од. — Сергій+фурнітура, грн | K1: Собівартість партії, грн
A2: Поріг замовлення для безкоштовної плюшки: | F2: ← ввести суму, рішення власника (задача 3D-P-004)
A3: 2026-07-26 | B3: ПРИКЛАД-001 | C3: 3 | D3: 60 | E3: =C3*D3 | F3: 1 | G3: — | H3: приклад — видалити | I3: 5 | J3: =D3+I3 | K3: =C3*J3
E4: =IF(C4="","",C4*D4) | J4: =IF(C4="","",D4+I4) | K4: =IF(C4="","",C4*J4)
E5: =IF(C5="","",C5*D5) | J5: =IF(C5="","",D5+I5) | K5: =IF(C5="","",C5*J5)
E6: =IF(C6="","",C6*D6) | J6: =IF(C6="","",D6+I6) | K6: =IF(C6="","",C6*J6)
E7: =IF(C7="","",C7*D7) | J7: =IF(C7="","",D7+I7) | K7: =IF(C7="","",C7*J7)
E8: =IF(C8="","",C8*D8) | J8: =IF(C8="","",D8+I8) | K8: =IF(C8="","",C8*J8)
E9: =IF(C9="","",C9*D9) | J9: =IF(C9="","",D9+I9) | K9: =IF(C9="","",C9*J9)
E10: =IF(C10="","",C10*D10) | J10: =IF(C10="","",D10+I10) | K10: =IF(C10="","",C10*J10)
E11: =IF(C11="","",C11*D11) | J11: =IF(C11="","",D11+I11) | K11: =IF(C11="","",C11*J11)
E12: =IF(C12="","",C12*D12) | J12: =IF(C12="","",D12+I12) | K12: =IF(C12="","",C12*J12)
E13: =IF(C13="","",C13*D13) | J13: =IF(C13="","",D13+I13) | K13: =IF(C13="","",C13*J13)
E14: =IF(C14="","",C14*D14) | J14: =IF(C14="","",D14+I14) | K14: =IF(C14="","",C14*J14)
E15: =IF(C15="","",C15*D15) | J15: =IF(C15="","",D15+I15) | K15: =IF(C15="","",C15*J15)
... E39: =IF(C39="","",C39*D39) | J39: =IF(C39="","",D39+I39) | K39: =IF(C39="","",C39*J39)

Sheet Наявність
A1: SKU | B1: Назва | C1: Надруковано всього, шт | D1: Брак всього, шт | E1: Продано на сайті, шт | F1: Видано як плюшка, шт | G1: Наявно зараз, шт
A2: =Номенклатура!A2 | B2: =IF(A2="","",Номенклатура!B2) | C2: =IF(A2="","",SUMIF('Друк-лог'!$B:$B,A2,'Друк-лог'!$C:$C)) | D2: =IF(A2="","",SUMIF('Друк-лог'!$B:$B,A2,'Друк-лог'!$E:$E)) | E2: =IF(A2="","",SUMIF(Продажі!$B:$B,A2,Продажі!$D:$D)) | F2: =IF(A2="","",SUMIF(Маркетингові_плюшки!$B:$B,A2,Маркетингові_плюшки!$F:$F)) | G2: =IF(A2="","",C2-D2-E2-F2)
A3: =Номенклатура!A3 | B3: =IF(A3="","",Номенклатура!B3) | C3: =IF(A3="","",SUMIF('Друк-лог'!$B:$B,A3,'Друк-лог'!$C:$C)) | D3: =IF(A3="","",SUMIF('Друк-лог'!$B:$B,A3,'Друк-лог'!$E:$E)) | E3: =IF(A3="","",SUMIF(Продажі!$B:$B,A3,Продажі!$D:$D)) | F3: =IF(A3="","",SUMIF(Маркетингові_плюшки!$B:$B,A3,Маркетингові_плюшки!$F:$F)) | G3: =IF(A3="","",C3-D3-E3-F3)
A4: =Номенклатура!A4 | B4: =IF(A4="","",Номенклатура!B4) | C4: =IF(A4="","",SUMIF('Друк-лог'!$B:$B,A4,'Друк-лог'!$C:$C)) | D4: =IF(A4="","",SUMIF('Друк-лог'!$B:$B,A4,'Друк-лог'!$E:$E)) | E4: =IF(A4="","",SUMIF(Продажі!$B:$B,A4,Продажі!$D:$D)) | F4: =IF(A4="","",SUMIF(Маркетингові_плюшки!$B:$B,A4,Маркетингові_плюшки!$F:$F)) | G4: =IF(A4="","",C4-D4-E4-F4)
A5: =Номенклатура!A5 | B5: =IF(A5="","",Номенклатура!B5) | C5: =IF(A5="","",SUMIF('Друк-лог'!$B:$B,A5,'Друк-лог'!$C:$C)) | D5: =IF(A5="","",SUMIF('Друк-лог'!$B:$B,A5,'Друк-лог'!$E:$E)) | E5: =IF(A5="","",SUMIF(Продажі!$B:$B,A5,Продажі!$D:$D)) | F5: =IF(A5="","",SUMIF(Маркетингові_плюшки!$B:$B,A5,Маркетингові_плюшки!$F:$F)) | G5: =IF(A5="","",C5-D5-E5-F5)
A6: =Номенклатура!A6 | B6: =IF(A6="","",Номенклатура!B6) | C6: =IF(A6="","",SUMIF('Друк-лог'!$B:$B,A6,'Друк-лог'!$C:$C)) | D6: =IF(A6="","",SUMIF('Друк-лог'!$B:$B,A6,'Друк-лог'!$E:$E)) | E6: =IF(A6="","",SUMIF(Продажі!$B:$B,A6,Продажі!$D:$D)) | F6: =IF(A6="","",SUMIF(Маркетингові_плюшки!$B:$B,A6,Маркетингові_плюшки!$F:$F)) | G6: =IF(A6="","",C6-D6-E6-F6)
A7: =Номенклатура!A7 | B7: =IF(A7="","",Номенклатура!B7) | C7: =IF(A7="","",SUMIF('Друк-лог'!$B:$B,A7,'Друк-лог'!$C:$C)) | D7: =IF(A7="","",SUMIF('Друк-лог'!$B:$B,A7,'Друк-лог'!$E:$E)) | E7: =IF(A7="","",SUMIF(Продажі!$B:$B,A7,Продажі!$D:$D)) | F7: =IF(A7="","",SUMIF(Маркетингові_плюшки!$B:$B,A7,Маркетингові_плюшки!$F:$F)) | G7: =IF(A7="","",C7-D7-E7-F7)
A8: =Номенклатура!A8 | B8: =IF(A8="","",Номенклатура!B8) | C8: =IF(A8="","",SUMIF('Друк-лог'!$B:$B,A8,'Друк-лог'!$C:$C)) | D8: =IF(A8="","",SUMIF('Друк-лог'!$B:$B,A8,'Друк-лог'!$E:$E)) | E8: =IF(A8="","",SUMIF(Продажі!$B:$B,A8,Продажі!$D:$D)) | F8: =IF(A8="","",SUMIF(Маркетингові_плюшки!$B:$B,A8,Маркетингові_плюшки!$F:$F)) | G8: =IF(A8="","",C8-D8-E8-F8)
A9: =Номенклатура!A9 | B9: =IF(A9="","",Номенклатура!B9) | C9: =IF(A9="","",SUMIF('Друк-лог'!$B:$B,A9,'Друк-лог'!$C:$C)) | D9: =IF(A9="","",SUMIF('Друк-лог'!$B:$B,A9,'Друк-лог'!$E:$E)) | E9: =IF(A9="","",SUMIF(Продажі!$B:$B,A9,Продажі!$D:$D)) | F9: =IF(A9="","",SUMIF(Маркетингові_плюшки!$B:$B,A9,Маркетингові_плюшки!$F:$F)) | G9: =IF(A9="","",C9-D9-E9-F9)
A10: =Номенклатура!A10 | B10: =IF(A10="","",Номенклатура!B10) | C10: =IF(A10="","",SUMIF('Друк-лог'!$B:$B,A10,'Друк-лог'!$C:$C)) | D10: =IF(A10="","",SUMIF('Друк-лог'!$B:$B,A10,'Друк-лог'!$E:$E)) | E10: =IF(A10="","",SUMIF(Продажі!$B:$B,A10,Продажі!$D:$D)) | F10: =IF(A10="","",SUMIF(Маркетингові_плюшки!$B:$B,A10,Маркетингові_плюшки!$F:$F)) | G10: =IF(A10="","",C10-D10-E10-F10)
A11: =Номенклатура!A11 | B11: =IF(A11="","",Номенклатура!B11) | C11: =IF(A11="","",SUMIF('Друк-лог'!$B:$B,A11,'Друк-лог'!$C:$C)) | D11: =IF(A11="","",SUMIF('Друк-лог'!$B:$B,A11,'Друк-лог'!$E:$E)) | E11: =IF(A11="","",SUMIF(Продажі!$B:$B,A11,Продажі!$D:$D)) | F11: =IF(A11="","",SUMIF(Маркетингові_плюшки!$B:$B,A11,Маркетингові_плюшки!$F:$F)) | G11: =IF(A11="","",C11-D11-E11-F11)
A12: =Номенклатура!A12 | B12: =IF(A12="","",Номенклатура!B12) | C12: =IF(A12="","",SUMIF('Друк-лог'!$B:$B,A12,'Друк-лог'!$C:$C)) | D12: =IF(A12="","",SUMIF('Друк-лог'!$B:$B,A12,'Друк-лог'!$E:$E)) | E12: =IF(A12="","",SUMIF(Продажі!$B:$B,A12,Продажі!$D:$D)) | F12: =IF(A12="","",SUMIF(Маркетингові_плюшки!$B:$B,A12,Маркетингові_плюшки!$F:$F)) | G12: =IF(A12="","",C12-D12-E12-F12)
A13: =Номенклатура!A13 | B13: =IF(A13="","",Номенклатура!B13) | C13: =IF(A13="","",SUMIF('Друк-лог'!$B:$B,A13,'Друк-лог'!$C:$C)) | D13: =IF(A13="","",SUMIF('Друк-лог'!$B:$B,A13,'Друк-лог'!$E:$E)) | E13: =IF(A13="","",SUMIF(Продажі!$B:$B,A13,Продажі!$D:$D)) | F13: =IF(A13="","",SUMIF(Маркетингові_плюшки!$B:$B,A13,Маркетингові_плюшки!$F:$F)) | G13: =IF(A13="","",C13-D13-E13-F13)
... A15: =Номенклатура!A15 | B15: =IF(A15="","",Номенклатура!B15) | C15: =IF(A15="","",SUMIF('Друк-лог'!$B:$B,A15,'Друк-лог'!$C:$C)) | D15: =IF(A15="","",SUMIF('Друк-лог'!$B:$B,A15,'Друк-лог'!$E:$E)) | E15: =IF(A15="","",SUMIF(Продажі!$B:$B,A15,Продажі!$D:$D)) | F15: =IF(A15="","",SUMIF(Маркетингові_плюшки!$B:$B,A15,Маркетингові_плюшки!$F:$F)) | G15: =IF(A15="","",C15-D15-E15-F15)

Sheet Аналітика
A1: Маржа-калькулятор по SKU (цінові сценарії, формула 50/50 після повернення собівартості)
A3: SKU | B3: Назва | C3: Собівартість Сергія, грн | D3: Витрати BoosterShop, грн | E3: Час друку, год | F3: % прибутку Сергію | G3: Ціна Консервативна | H3: Ціна Середня | I3: Ціна Оптимістична | J3: Маржа BoosterShop Консерв, грн | K3: Маржа BoosterShop Середня, грн | L3: Маржа BoosterShop Оптим, грн | M3: Нараховано Сергію (Середня), грн | N3: Прибуток Сергію/год друку (Середня), грн
A4: =Номенклатура!A2 | B4: =IF(A4="","",Номенклатура!B2) | C4: =IF(A4="","",Номенклатура!K2) | E4: =IF(A4="","",Номенклатура!G2) | F4: 0.5 | J4: =IF(OR(A4="",G4=""),"",IF(G4-C4-D4<0,"збиток",(G4-C4-D4)*(1-F4))) | K4: =IF(OR(A4="",H4=""),"",IF(H4-C4-D4<0,"збиток",(H4-C4-D4)*(1-F4))) | L4: =IF(OR(A4="",I4=""),"",IF(I4-C4-D4<0,"збиток",(I4-C4-D4)*(1-F4))) | M4: =IF(OR(A4="",H4=""),"",IF(H4-C4-D4<0,"збиток",C4+F4*(H4-C4-D4))) | N4: =IF(OR(E4="",E4=0,M4=""),"",IF(ISNUMBER(M4),M4/E4,"збиток"))
A5: =Номенклатура!A3 | B5: =IF(A5="","",Номенклатура!B3) | C5: =IF(A5="","",Номенклатура!K3) | E5: =IF(A5="","",Номенклатура!G3) | F5: 0.5 | J5: =IF(OR(A5="",G5=""),"",IF(G5-C5-D5<0,"збиток",(G5-C5-D5)*(1-F5))) | K5: =IF(OR(A5="",H5=""),"",IF(H5-C5-D5<0,"збиток",(H5-C5-D5)*(1-F5))) | L5: =IF(OR(A5="",I5=""),"",IF(I5-C5-D5<0,"збиток",(I5-C5-D5)*(1-F5))) | M5: =IF(OR(A5="",H5=""),"",IF(H5-C5-D5<0,"збиток",C5+F5*(H5-C5-D5))) | N5: =IF(OR(E5="",E5=0,M5=""),"",IF(ISNUMBER(M5),M5/E5,"збиток"))
A6: =Номенклатура!A4 | B6: =IF(A6="","",Номенклатура!B4) | C6: =IF(A6="","",Номенклатура!K4) | E6: =IF(A6="","",Номенклатура!G4) | F6: 0.5 | J6: =IF(OR(A6="",G6=""),"",IF(G6-C6-D6<0,"збиток",(G6-C6-D6)*(1-F6))) | K6: =IF(OR(A6="",H6=""),"",IF(H6-C6-D6<0,"збиток",(H6-C6-D6)*(1-F6))) | L6: =IF(OR(A6="",I6=""),"",IF(I6-C6-D6<0,"збиток",(I6-C6-D6)*(1-F6))) | M6: =IF(OR(A6="",H6=""),"",IF(H6-C6-D6<0,"збиток",C6+F6*(H6-C6-D6))) | N6: =IF(OR(E6="",E6=0,M6=""),"",IF(ISNUMBER(M6),M6/E6,"збиток"))
A7: =Номенклатура!A5 | B7: =IF(A7="","",Номенклатура!B5) | C7: =IF(A7="","",Номенклатура!K5) | E7: =IF(A7="","",Номенклатура!G5) | F7: 0.5 | J7: =IF(OR(A7="",G7=""),"",IF(G7-C7-D7<0,"збиток",(G7-C7-D7)*(1-F7))) | K7: =IF(OR(A7="",H7=""),"",IF(H7-C7-D7<0,"збиток",(H7-C7-D7)*(1-F7))) | L7: =IF(OR(A7="",I7=""),"",IF(I7-C7-D7<0,"збиток",(I7-C7-D7)*(1-F7))) | M7: =IF(OR(A7="",H7=""),"",IF(H7-C7-D7<0,"збиток",C7+F7*(H7-C7-D7))) | N7: =IF(OR(E7="",E7=0,M7=""),"",IF(ISNUMBER(M7),M7/E7,"збиток"))
A8: =Номенклатура!A6 | B8: =IF(A8="","",Номенклатура!B6) | C8: =IF(A8="","",Номенклатура!K6) | E8: =IF(A8="","",Номенклатура!G6) | F8: 0.5 | J8: =IF(OR(A8="",G8=""),"",IF(G8-C8-D8<0,"збиток",(G8-C8-D8)*(1-F8))) | K8: =IF(OR(A8="",H8=""),"",IF(H8-C8-D8<0,"збиток",(H8-C8-D8)*(1-F8))) | L8: =IF(OR(A8="",I8=""),"",IF(I8-C8-D8<0,"збиток",(I8-C8-D8)*(1-F8))) | M8: =IF(OR(A8="",H8=""),"",IF(H8-C8-D8<0,"збиток",C8+F8*(H8-C8-D8))) | N8: =IF(OR(E8="",E8=0,M8=""),"",IF(ISNUMBER(M8),M8/E8,"збиток"))
A9: =Номенклатура!A7 | B9: =IF(A9="","",Номенклатура!B7) | C9: =IF(A9="","",Номенклатура!K7) | E9: =IF(A9="","",Номенклатура!G7) | F9: 0.5 | J9: =IF(OR(A9="",G9=""),"",IF(G9-C9-D9<0,"збиток",(G9-C9-D9)*(1-F9))) | K9: =IF(OR(A9="",H9=""),"",IF(H9-C9-D9<0,"збиток",(H9-C9-D9)*(1-F9))) | L9: =IF(OR(A9="",I9=""),"",IF(I9-C9-D9<0,"збиток",(I9-C9-D9)*(1-F9))) | M9: =IF(OR(A9="",H9=""),"",IF(H9-C9-D9<0,"збиток",C9+F9*(H9-C9-D9))) | N9: =IF(OR(E9="",E9=0,M9=""),"",IF(ISNUMBER(M9),M9/E9,"збиток"))
A10: =Номенклатура!A8 | B10: =IF(A10="","",Номенклатура!B8) | C10: =IF(A10="","",Номенклатура!K8) | E10: =IF(A10="","",Номенклатура!G8) | F10: 0.5 | J10: =IF(OR(A10="",G10=""),"",IF(G10-C10-D10<0,"збиток",(G10-C10-D10)*(1-F10))) | K10: =IF(OR(A10="",H10=""),"",IF(H10-C10-D10<0,"збиток",(H10-C10-D10)*(1-F10))) | L10: =IF(OR(A10="",I10=""),"",IF(I10-C10-D10<0,"збиток",(I10-C10-D10)*(1-F10))) | M10: =IF(OR(A10="",H10=""),"",IF(H10-C10-D10<0,"збиток",C10+F10*(H10-C10-D10))) | N10: =IF(OR(E10="",E10=0,M10=""),"",IF(ISNUMBER(M10),M10/E10,"збиток"))
A11: =Номенклатура!A9 | B11: =IF(A11="","",Номенклатура!B9) | C11: =IF(A11="","",Номенклатура!K9) | E11: =IF(A11="","",Номенклатура!G9) | F11: 0.5 | J11: =IF(OR(A11="",G11=""),"",IF(G11-C11-D11<0,"збиток",(G11-C11-D11)*(1-F11))) | K11: =IF(OR(A11="",H11=""),"",IF(H11-C11-D11<0,"збиток",(H11-C11-D11)*(1-F11))) | L11: =IF(OR(A11="",I11=""),"",IF(I11-C11-D11<0,"збиток",(I11-C11-D11)*(1-F11))) | M11: =IF(OR(A11="",H11=""),"",IF(H11-C11-D11<0,"збиток",C11+F11*(H11-C11-D11))) | N11: =IF(OR(E11="",E11=0,M11=""),"",IF(ISNUMBER(M11),M11/E11,"збиток"))
A12: =Номенклатура!A10 | B12: =IF(A12="","",Номенклатура!B10) | C12: =IF(A12="","",Номенклатура!K10) | E12: =IF(A12="","",Номенклатура!G10) | F12: 0.5 | J12: =IF(OR(A12="",G12=""),"",IF(G12-C12-D12<0,"збиток",(G12-C12-D12)*(1-F12))) | K12: =IF(OR(A12="",H12=""),"",IF(H12-C12-D12<0,"збиток",(H12-C12-D12)*(1-F12))) | L12: =IF(OR(A12="",I12=""),"",IF(I12-C12-D12<0,"збиток",(I12-C12-D12)*(1-F12))) | M12: =IF(OR(A12="",H12=""),"",IF(H12-C12-D12<0,"збиток",C12+F12*(H12-C12-D12))) | N12: =IF(OR(E12="",E12=0,M12=""),"",IF(ISNUMBER(M12),M12/E12,"збиток"))
A13: =Номенклатура!A11 | B13: =IF(A13="","",Номенклатура!B11) | C13: =IF(A13="","",Номенклатура!K11) | E13: =IF(A13="","",Номенклатура!G11) | F13: 0.5 | J13: =IF(OR(A13="",G13=""),"",IF(G13-C13-D13<0,"збиток",(G13-C13-D13)*(1-F13))) | K13: =IF(OR(A13="",H13=""),"",IF(H13-C13-D13<0,"збиток",(H13-C13-D13)*(1-F13))) | L13: =IF(OR(A13="",I13=""),"",IF(I13-C13-D13<0,"збиток",(I13-C13-D13)*(1-F13))) | M13: =IF(OR(A13="",H13=""),"",IF(H13-C13-D13<0,"збиток",C13+F13*(H13-C13-D13))) | N13: =IF(OR(E13="",E13=0,M13=""),"",IF(ISNUMBER(M13),M13/E13,"збиток"))
A14: =Номенклатура!A12 | B14: =IF(A14="","",Номенклатура!B12) | C14: =IF(A14="","",Номенклатура!K12) | E14: =IF(A14="","",Номенклатура!G12) | F14: 0.5 | J14: =IF(OR(A14="",G14=""),"",IF(G14-C14-D14<0,"збиток",(G14-C14-D14)*(1-F14))) | K14: =IF(OR(A14="",H14=""),"",IF(H14-C14-D14<0,"збиток",(H14-C14-D14)*(1-F14))) | L14: =IF(OR(A14="",I14=""),"",IF(I14-C14-D14<0,"збиток",(I14-C14-D14)*(1-F14))) | M14: =IF(OR(A14="",H14=""),"",IF(H14-C14-D14<0,"збиток",C14+F14*(H14-C14-D14))) | N14: =IF(OR(E14="",E14=0,M14=""),"",IF(ISNUMBER(M14),M14/E14,"збиток"))
A15: =Номенклатура!A13 | B15: =IF(A15="","",Номенклатура!B13) | C15: =IF(A15="","",Номенклатура!K13) | E15: =IF(A15="","",Номенклатура!G13) | F15: 0.5 | J15: =IF(OR(A15="",G15=""),"",IF(G15-C15-D15<0,"збиток",(G15-C15-D15)*(1-F15))) | K15: =IF(OR(A15="",H15=""),"",IF(H15-C15-D15<0,"збиток",(H15-C15-D15)*(1-F15))) | L15: =IF(OR(A15="",I15=""),"",IF(I15-C15-D15<0,"збиток",(I15-C15-D15)*(1-F15))) | M15: =IF(OR(A15="",H15=""),"",IF(H15-C15-D15<0,"збиток",C15+F15*(H15-C15-D15))) | N15: =IF(OR(E15="",E15=0,M15=""),"",IF(ISNUMBER(M15),M15/E15,"збиток"))
... A17: =Номенклатура!A15 | B17: =IF(A17="","",Номенклатура!B15) | C17: =IF(A17="","",Номенклатура!K15) | E17: =IF(A17="","",Номенклатура!G15) | F17: 0.5 | J17: =IF(OR(A17="",G17=""),"",IF(G17-C17-D17<0,"збиток",(G17-C17-D17)*(1-F17))) | K17: =IF(OR(A17="",H17=""),"",IF(H17-C17-D17<0,"збиток",(H17-C17-D17)*(1-F17))) | L17: =IF(OR(A17="",I17=""),"",IF(I17-C17-D17<0,"збиток",(I17-C17-D17)*(1-F17))) | M17: =IF(OR(A17="",H17=""),"",IF(H17-C17-D17<0,"збиток",C17+F17*(H17-C17-D17))) | N17: =IF(OR(E17="",E17=0,M17=""),"",IF(ISNUMBER(M17),M17/E17,"збиток"))
A19: Ринкові орієнтири (зовнішні дані) — оновлено 2026-07-29
A20: Дослідження 2026-07-29: 30 перевірених лотів (22 Prom.ua у грн, 9 Etsy у $; 1 Etsy-лот з попередньої перевірки 2026-07-28 знято з продажу — виключено). Це орієнтир по діапазону цін ринку, НЕ готова РРЦ — перед фіксацією РРЦ звірити із реальною собівартістю і часом друку Сергія на 3-5 власних SKU (задача 3D-P-003 лишається в статусі «в роботі» до цієї звірки).
A21: Джерело | B21: Товар | C21: Ціна | D21: Валюта | E21: Дата перевірки | F21: Посилання / примітка
A22: Prom.ua | B22: Фігурка Ведмідь Баар (гра), 110мм | C22: 160 | D22: UAH | E22: prom.ua/ua/m597215714077015821 — одноколірний PLA
A23: Prom.ua | B23: Фігурка Аксолотль Майнкрафт, 8см | C23: 90 | D23: UAH | E23: prom.ua/ua/m-2537173792697582487
A24: Prom.ua | B24: Рухлива фігурка Кіт з Сімс, шарнірна | C24: 200 | D24: UAH | E24: prom.ua/ua/m5293519234516252495
A25: Prom.ua | B25: AC2 Брелок Порожній лицар (гра), keychain | C25: 178 | D25: UAH | E25: prom.ua/ua/p3132251578 — акція, було 187
A26: Prom.ua | B26: AC2 Брелок «Як приручити дракона» | C26: 188 | D26: UAH | E26: prom.ua/ua/p3132248531 — акція, було 197
A27: Prom.ua | B27: AC2 Фігурка-брелок K-Pop Derby | C27: 215 | D27: UAH | E27: prom.ua/ua/p3132251584 — акція, було 226
A28: Prom.ua | B28: AC2 Брелок Соник | C28: 218 | D28: UAH | E28: prom.ua/ua/p3132251587 — акція, було 229
A29: Prom.ua | B29: AC2 Фігурка-брелок K-Pop Zoe | C29: 227 | D29: UAH | E29: prom.ua/ua/p3132251582 — акція, було 238
A30: Prom.ua | B30: Фігурка Аксолотль Майнкрафт, 16см | C30: 250 | D30: UAH | E30: prom.ua/ua/m7736287518879278678
A31: Prom.ua | B31: Фігурка Прототип Poppy Playtime Ch5, кольоровий | C31: 250 | D31: UAH | E31: prom.ua/ua/m6175503276994557169
A32: Prom.ua | B32: Іграшка Six Seven, шарнірна, 12см | C32: 275 | D32: UAH | E32: prom.ua/ua/m-3682311495060361450 — акція, було 550
A33: Prom.ua | B33: Фігурка-антистрес Дракон рухомий, 20см | C33: 280 | D33: UAH | E33: prom.ua/ua/m-1307140614863278157
... A40: Prom.ua | B40: Комплект фігурок-охоронців Squid Game, 3 шт/компл. | C40: 450 | D40: UAH | E40: prom.ua/ua/m3765887112151365736 — ціна за комплект, не за од.
A41: Prom.ua | B41: Набір фігурок Meccha Chameleon, 10 шт/компл. | C41: 476,34 | D41: UAH | E41: prom.ua/ua/m4244796096804350994 — акція, було 934; ціна за комплект
A42: Prom.ua | B42: Реалістична фігурка Poppy Playtime, ручний розпис | C42: 500 | D42: UAH | E42: prom.ua/ua/m-8758516164790332419 — акція, було 350→ уточнити напрямок знижки
A43: Prom.ua | B43: Колекційна фігурка Скелет Дракона, ручний розпис | C43: 1000 | D43: UAH | E43: prom.ua/ua/m-5160638727247461934 — декоративна статуетка
A44: Prom.ua | B44: Фігурка на замовлення за фото, ручний розпис | C44: 3000 | D44: UAH | E44: prom.ua/ua/m6705495101661827516 — кастом+розпис, аутлаєр, не пряма аналогія
A45: Etsy | B45: 3D Printed Pokemon Figurines — Made to Order (Pooch3Prints) | C45: 5 | D45: USD | E45: etsy.com/listing/... — одноколірний PLA, без відгуків
A46: Etsy | B46: Sprite Gaming Collectible Figure, PLA | C46: 5.59 | D46: USD | E46: similar-items — акція, було 6.99
A47: Etsy | B47: Fort Sprite Figure — Collectible Game Sprite Statue / keychain | C47: 5.59 | D47: USD | E47: similar-items — акція, було 6.99
A48: Etsy | B48: Hand-Painted Rocky Figure (Project Hail Mary) | C48: 18.1 | D48: USD | E48: similar-items — акція, було 22.62, ручний розпис
A49: Etsy | B49: 3D Printed Mimikyu Pokémon Figurine, ручний розпис | C49: 27.5 | D49: USD | E49: etsy.com/listing/1294929392 — перевірено 2026-07-28
...
